Workbook
Name Slicer_Brand: #N/A
Name Slicer_Category: #N/A
Name Slicer_City: #N/A
Name Slicer_Delivery_Status: #N/A
Name Slicer_Months__Order_Date2: #N/A
Name Slicer_Payment_Mode: #N/A
Name Slicer_Product: #N/A
Name Slicer_Product1: #N/A
Name Slicer_Return_Status: #N/A
Name Slicer_Seller: #N/A
Name Slicer_State: #N/A

Sheet Dashboard

Sheet Order Data
A1: Order ID | B1: Order Date | C1: Customer Name | D1: City | E1: State | F1: Category | G1: Product | H1: Brand | I1: Seller | J1: Quantity | K1: Unit Price | L1: Discount | M1: Revenue | N1: Profit | O1: Payment Mode | P1: Delivery Status | Q1: Rating | R1: Return Status
A2: OD1796990001 | B2: 45782 | C2: Shilpa Shetty | D2: Chennai | E2: Tamil Nadu | F2: Electronics | G2: Wireless Earbuds | H2: boAt | I2: RetailNet | J2: 4 | K2: 40597 | L2: 0.2 | M2: =J2*K2*(1-L2) -> 129910.4 | N2: =M2*0.21 -> 27281.184 | O2: Credit Card | P2: Delivered | Q2: 5 | R2: No Return
A3: OD2267880002 | B3: 46060 | C3: Rohan Das | D3: Chennai | E3: Tamil Nadu | F3: Beauty & Grooming | G3: Face Wash | H3: Nivea | I3: RetailNet | J3: 4 | K3: 546 | L3: 0.2 | M3: =J3*K3*(1-L3) -> 1747.2 | N3: =M3*0.21 -> 366.912 | O3: Debit Card | P3: Delivered | Q3: 3 | R3: No Return
A4: OD3554840003 | B4: 46031 | C4: Ananya Iyer | D4: Kolkata | E4: West Bengal | F4: Electronics | G4: Smartphone | H4: Realme | I4: RetailNet | J4: 2 | K4: 17147 | L4: 0.05 | M4: =J4*K4*(1-L4) -> 32579.3 | N4: =M4*0.23 -> 7493.239 | O4: Debit Card | P4: Delivered | Q4: 3 | R4: No Return | T4: =AVERAGE(Table1[Rating]) -> 3.966782
A5: OD5817020004 | B5: 46077 | C5: Yash Wardhan | D5: Kolkata | E5: West Bengal | F5: Electronics | G5: Smartphone | H5: Realme | I5: RetailNet | J5: 1 | K5: 5514 | L5: 0 | M5: =J5*K5*(1-L5) -> 5514 | N5: =M5*0.18 -> 992.52 | O5: Credit Card | P5: Delivered | Q5: 5 | R5: No Return
A6: OD7170960005 | B6: 45819 | C6: Divya Dutta | D6: Bangalore | E6: Karnataka | F6: Electronics | G6: Wireless Earbuds | H6: boAt | I6: IndiFlashMart | J6: 1 | K6: 56364 | L6: 0.2 | M6: =J6*K6*(1-L6) -> 45091.2 | N6: =M6*0.23 -> 10370.976 | O6: Net Banking | P6: Delivered | Q6: 5 | R6: No Return
A7: OD2893940006 | B7: 46049 | C7: Shilpa Shetty | D7: Mumbai | E7: Maharashtra | F7: Home & Kitchen | G7: Bedsheet Set | H7: Bombay Dyeing | I7: SaneRetails | J7: 1 | K7: 3192 | L7: 0.15 | M7: =J7*K7*(1-L7) -> 2713.2 | N7: =M7*0.21 -> 569.772 | O7: Net Banking | P7: Delivered | Q7: 5 | R7: No Return | U7: =COUNTA(Table1[Customer Name]) -> 1500
A8: OD9199100007 | B8: 45795 | C8: Vikram Singh | D8: Mumbai | E8: Maharashtra | F8: Electronics | G8: Smart TV | H8: Samsung | I8: IndiFlashMart | J8: 1 | K8: 43068 | L8: 0.15 | M8: =J8*K8*(1-L8) -> 36607.8 | N8: =M8*0.2 -> 7321.56 | O8: Cash on Delivery (COD) | P8: Delivered | Q8: 3 | R8: No Return | U8: =AVERAGE(Table1[Unit Price]) -> 9994.8873
A9: OD9233690008 | B9: 45811 | C9: Shilpa Shetty | D9: Guwahati | E9: Assam | F9: Home & Kitchen | G9: Bedsheet Set | H9: Bombay Dyeing | I9: OmniTechRetail | J9: 2 | K9: 359 | L9: 0.05 | M9: =J9*K9*(1-L9) -> 682.1 | N9: =M9*0.15 -> 102.315 | O9: Debit Card | P9: Delivered | Q9: 5 | R9: No Return | U9: =AVERAGE(Table1[Revenue]) -> 13610.033
A10: OD6105490009 | B10: 45678 | C10: Rohan Das | D10: Kochi | E10: Kerala | F10: Beauty & Grooming | G10: Sunscreen | H10: Neutrogena | I10: TrueComRetail | J10: 4 | K10: 201 | L10: 0 | M10: =J10*K10*(1-L10) -> 804 | N10: =-0.08*M10 -> -64.32 | O10: Net Banking | P10: Returned | Q10: 1 | R10: Returned
A11: OD4288370010 | B11: 45714 | C11: Aditi Rao | D11: Lucknow | E11: Uttar Pradesh | F11: Home & Kitchen | G11: Bedsheet Set | H11: Bombay Dyeing | I11: OmniTechRetail | J11: 1 | K11: 819 | L11: 0.2 | M11: =J11*K11*(1-L11) -> 655.2 | N11: =M11*0.14 -> 91.728 | O11: Net Banking | P11: Delivered | Q11: 4 | R11: No Return
A12: OD2389910011 | B12: 45917 | C12: Deepak Kumar | D12: Chandigarh | E12: Punjab | F12: Home & Kitchen | G12: Air Fryer | H12: Kent | I12: OmniTechRetail | J12: 1 | K12: 4017 | L12: 0.15 | M12: =J12*K12*(1-L12) -> 3414.45 | N12: =M12*0.13 -> 443.8785 | O12: UPI | P12: Delivered | Q12: 3 | R12: No Return
A13: OD7594310012 | B13: 46002 | C13: Ananya Iyer | D13: Guwahati | E13: Assam | F13: Clothing & Fashion | G13: Sports Shoes | H13: Puma | I13: SuperComNet | J13: 1 | K13: 1906 | L13: 0 | M13: =J13*K13*(1-L13) -> 1906 | N13: =M13*0.22 -> 419.32 | O13: Net Banking | P13: Delivered | Q13: 5 | R13: No Return
A14: OD1468310013 | B14: 46037 | C14: Kriti Malhotra | D14: Mumbai | E14: Maharashtra | F14: Electronics | G14: Wireless Earbuds | H14: boAt | I14: RetailNet | J14: 1 | K14: 32563 | L14: 0.2 | M14: =J14*K14*(1-L14) -> 26050.4 | N14: =M14*0.2 -> 5210.08 | O14: UPI | P14: Delivered | Q14: 3 | R14: No Return
A15: OD7647860014 | B15: 45707 | C15: Deepak Kumar | D15: Delhi | E15: Delhi | F15: Home & Kitchen | G15: Air Fryer | H15: Kent | I15: SaneRetails | J15: 1 | K15: 5878 | L15: 0.1 | M15: =J15*K15*(1-L15) -> 5290.2 | N15: =M15*0.25 -> 1322.55 | O15: Net Banking | P15: Delivered | Q15: 4 | R15: No Return
A16: OD2519700015 | B16: 45907 | C16: Vikram Singh | D16: Hyderabad | E16: Telangana | F16: Clothing & Fashion | G16: Casual T-Shirt | H16: Roadster | I16: SuperComNet | J16: 2 | K16: 3941 | L16: 0.1 | M16: =J16*K16*(1-L16) -> 7093.8 | N16: =M16*0.14 -> 993.132 | O16: Net Banking | P16: Delivered | Q16: 5 | R16: No Return
A17: OD5762740016 | B17: 46081 | C17: Aarav Sharma | D17: Patna | E17: Bihar | F17: Clothing & Fashion | G17: Casual T-Shirt | H17: Roadster | I17: TrueComRetail | J17: 1 | K17: 4389 | L17: 0.05 | M17: =J17*K17*(1-L17) -> 4169.55 | N17: =M17*0.19 -> 792.2145 | O17: Credit Card | P17: Delivered | Q17: 4 | R17: No Return
A18: OD5863060017 | B18: 45922 | C18: Aditi Rao | D18: Delhi | E18: Delhi | F18: Beauty & Grooming | G18: Sunscreen | H18: Neutrogena | I18: RetailNet | J18: 2 | K18: 192 | L18: 0.15 | M18: =J18*K18*(1-L18) -> 326.4 | N18: =M18*0.21 -> 68.544 | O18: UPI | P18: Delivered | Q18: 4 | R18: No Return
A19: OD2394080018 | B19: 45694 | C19: Vikram Singh | D19: Kochi | E19: Kerala | F19: Home & Kitchen | G19: Air Fryer | H19: Kent | I19: OmniTechRetail | J19: 4 | K19: 1168 | L19: 0.05 | M19: =J19*K19*(1-L19) -> 4438.4 | N19: =M19*0.1 -> 443.84 | O19: Net Banking | P19: Delivered | Q19: 5 | R19: No Return
A20: OD6689710019 | B20: 46029 | C20: Neha Gupta | D20: Ahmedabad | E20: Gujarat | F20: Beauty & Grooming | G20: Beard Trimmer | H20: L'Oreal | I20: TrueComRetail | J20: 1 | K20: 2374 | L20: 0.05 | M20: =J20*K20*(1-L20) -> 2255.3 | N20: =M20*0.1 -> 225.53 | O20: Cash on Delivery (COD) | P20: Delivered | Q20: 3 | R20: No Return
A21: OD5164440020 | B21: 45773 | C21: Vivek Agnihotri | D21: Bhopal | E21: Madhya Pradesh | F21: Home & Kitchen | G21: Non-Stick Pan | H21: Hawkins | I21: OmniTechRetail | J21: 2 | K21: 2406 | L21: 0 | M21: =J21*K21*(1-L21) -> 4812 | N21: =M21*0.25 -> 1203 | O21: Debit Card | P21: Delivered | Q21: 3 | R21: No Return
A22: OD7944860021 | B22: 46096 | C22: Neha Gupta | D22: Lucknow | E22: Uttar Pradesh | F22: Beauty & Grooming | G22: Face Wash | H22: Nivea | I22: RetailNet | J22: 1 | K22: 2163 | L22: 0 | M22: =J22*K22*(1-L22) -> 2163 | N22: =M22*0.15 -> 324.45 | O22: UPI | P22: Delivered | Q22: 5 | R22: No Return
A23: OD7028500022 | B23: 46083 | C23: Karan Johar | D23: Chandigarh | E23: Punjab | F23: Electronics | G23: Power Bank | H23: Mi | I23: IndiFlashMart | J23: 2 | K23: 61585 | L23: 0 | M23: =J23*K23*(1-L23) -> 123170 | N23: =M23*0.15 -> 18475.5 | O23: Net Banking | P23: Delivered | Q23: 4 | R23: No Return
A24: OD4198650023 | B24: 45960 | C24: Amit Verma | D24: Chandigarh | E24: Punjab | F24: Beauty & Grooming | G24: Hair Dryer | H24: Philips | I24: TrueComRetail | J24: 1 | K24: 1887 | L24: 0.15 | M24: 0 | N24: 0 | O24: Debit Card | P24: Cancelled | R24: Not Applicable
A25: OD6063100024 | B25: 46061 | C25: Aarav Sharma | D25: Chennai | E25: Tamil Nadu | F25: Beauty & Grooming | G25: Perfume | H25: Beardo | I25: TrueComRetail | J25: 1 | K25: 2261 | L25: 0.15 | M25: =J25*K25*(1-L25) -> 1921.85 | N25: =M25*0.25 -> 480.4625 | O25: Credit Card | P25: Delivered | Q25: 5 | R25: No Return
A26: OD3902980025 | B26: 45752 | C26: Sunil Gavaskar | D26: Mumbai | E26: Maharashtra | F26: Electronics | G26: Smartwatch | H26: Noise | I26: IndiFlashMart | J26: 1 | K26: 63361 | L26: 0.05 | M26: =J26*K26*(1-L26) -> 60192.95 | N26: =M26*0.13 -> 7825.0835 | O26: UPI | P26: Delivered | Q26: 4 | R26: No Return
A27: OD3811000026 | B27: 45720 | C27: Divya Dutta | D27: Ahmedabad | E27: Gujarat | F27: Beauty & Grooming | G27: Beard Trimmer | H27: L'Oreal | I27: TrueComRetail | J27: 1 | K27: 2103 | L27: 0.15 | M27: =J27*K27*(1-L27) -> 1787.55 | N27: =M27*0.22 -> 393.261 | O27: Cash on Delivery (COD) | P27: Delivered | Q27: 5 | R27: No Return
A28: OD6618100027 | B28: 45664 | C28: Priya Patel | D28: Lucknow | E28: Uttar Pradesh | F28: Home & Kitchen | G28: Air Fryer | H28: Kent | I28: SaneRetails | J28: 1 | K28: 2433 | L28: 0 | M28: =J28*K28*(1-L28) -> 2433 | N28: =M28*0.17 -> 413.61 | O28: Cash on Delivery (COD) | P28: Delivered | Q28: 5 | R28: No Return
A29: OD9237890028 | B29: 45801 | C29: Sunil Gavaskar | D29: Bhopal | E29: Madhya Pradesh | F29: Home & Kitchen | G29: Non-Stick Pan | H29: Hawkins | I29: OmniTechRetail | J29: 1 | K29: 5318 | L29: 0.05 | M29: =J29*K29*(1-L29) -> 5052.1 | N29: =M29*0.24 -> 1212.504 | O29: Cash on Delivery (COD) | P29: Delivered | Q29: 4 | R29: No Return
A30: OD6626240029 | B30: 45712 | C30: Meera Bai | D30: Chandigarh | E30: Punjab | F30: Electronics | G30: Wireless Earbuds | H30: boAt | I30: RetailNet | J30: 1 | K30: 27907 | L30: 0.2 | M30: =J30*K30*(1-L30) -> 22325.6 | N30: =-0.08*M30 -> -1786.048 | O30: Credit Card | P30: Returned | Q30: 1 | R30: Returned
A31: OD6855220030 | B31: 46060 | C31: Alok Nath | D31: Delhi | E31: Delhi | F31: Electronics | G31: Smartphone | H31: Realme | I31: RetailNet | J31: 1 | K31: 24250 | L31: 0 | M31: =J31*K31*(1-L31) -> 24250 | N31: =M31*0.1 -> 2425 | O31: Cash on Delivery (COD) | P31: Delivered | Q31: 3 | R31: No Return
A32: OD2812950031 | B32: 46089 | C32: Amit Verma | D32: Jaipur | E32: Rajasthan | F32: Beauty & Grooming | G32: Face Wash | H32: Nivea | I32: TrueComRetail | J32: 1 | K32: 2190 | L32: 0.1 | M32: =J32*K32*(1-L32) -> 1971 | N32: =M32*0.15 -> 295.65 | O32: Cash on Delivery (COD) | P32: Delivered | Q32: 5 | R32: No Return
A33: OD8837560032 | B33: 45753 | C33: Karan Johar | D33: Mumbai | E33: Maharashtra | F33: Beauty & Grooming | G33: Sunscreen | H33: Neutrogena | I33: RetailNet | J33: 1 | K33: 791 | L33: 0.05 | M33: =J33*K33*(1-L33) -> 751.45 | N33: =M33*0.19 -> 142.7755 | O33: Net Banking | P33: Delivered | Q33: 4 | R33: No Return
A34: OD3323770033 | B34: 45986 | C34: Divya Dutta | D34: Pune | E34: Maharashtra | F34: Beauty & Grooming | G34: Hair Dryer | H34: Philips | I34: RetailNet | J34: 1 | K34: 532 | L34: 0.15 | M34: =J34*K34*(1-L34) -> 452.2 | N34: =M34*0.26 -> 117.572 | O34: Credit Card | P34: Delivered | Q34: 5 | R34: No Return
A35: OD2702390034 | B35: 45852 | C35: Riya Sen | D35: Delhi | E35: Delhi | F35: Electronics | G35: Smartwatch | H35: Noise | I35: RetailNet | J35: 1 | K35: 62874 | L35: 0 | M35: =J35*K35*(1-L35) -> 62874 | N35: =M35*0.22 -> 13832.28 | O35: UPI | P35: Delivered | Q35: 4 | R35: No Return
A36: OD1865510035 | B36: 45936 | C36: Aarav Sharma | D36: Jaipur | E36: Rajasthan | F36: Beauty & Grooming | G36: Beard Trimmer | H36: L'Oreal | I36: TrueComRetail | J36: 2 | K36: 408 | L36: 0.05 | M36: =J36*K36*(1-L36) -> 775.2 | N36: =M36*0.25 -> 193.8 | O36: Net Banking | P36: Delivered | Q36: 4 | R36: No Return
A37: OD3430780036 | B37: 46075 | C37: Pooja Nair | D37: Jaipur | E37: Rajasthan | F37: Electronics | G37: Wireless Earbuds | H37: boAt | I37: RetailNet | J37: 2 | K37: 24079 | L37: 0.05 | M37: =J37*K37*(1-L37) -> 45750.1 | N37: =M37*0.24 -> 10980.024 | O37: Net Banking | P37: Delivered | Q37: 5 | R37: No Return
A38: OD1159150037 | B38: 46094 | C38: Priya Patel | D38: Lucknow | E38: Uttar Pradesh | F38: Clothing & Fashion | G38: Leather Jacket | H38: Zara | I38: TrueComRetail | J38: 1 | K38: 1891 | L38: 0.15 | M38: =J38*K38*(1-L38) -> 1607.35 | N38: =M38*0.21 -> 337.5435 | O38: Credit Card | P38: Delivered | Q38: 4 | R38: No Return
A39: OD7371940038 | B39: 45668 | C39: Rohan Das | D39: Mumbai | E39: Maharashtra | F39: Electronics | G39: Smart TV | H39: Samsung | I39: IndiFlashMart | J39: 1 | K39: 60770 | L39: 0.2 | M39: =J39*K39*(1-L39) -> 48616 | N39: =M39*0.17 -> 8264.72 | O39: Cash on Delivery (COD) | P39: Delivered | Q39: 4 | R39: No Return
A40: OD8111680039 | B40: 45865 | C40: Jyoti Mishra | D40: Lucknow | E40: Uttar Pradesh | F40: Beauty & Grooming | G40: Sunscreen | H40: Neutrogena | I40: TrueComRetail | J40: 1 | K40: 888 | L40: 0.1 | M40: =J40*K40*(1-L40) -> 799.2 | N40: =M40*0.17 -> 135.864 | O40: Net Banking | P40: Delivered | Q40: 5 | R40: No Return
...

Sheet Dashboard Summary
B2: FLIPKART PERFORMANCE DASHBOARD
B5: Total Orders | C5: Total Revenue | E5: Total Profit | F5: Average Rating | M5: Tumhare dataset me ye columns hain: | T5: 📦 Total Orders
B6: =COUNTA('Order Data'!A2:A1501) -> 1500 | C6: =SUM('Order Data'!M2:M1501) -> 20415050 | E6: =SUM('Order Data'!N2:N1501) -> 3586218.8 | F6: =AVERAGE('Order Data'!Q2:Q1501) -> 3.966782 | T6: 💰 Total Revenue
M7: Order ID | T7: 📈 Total Profit
M8: Order Date | T8: ⭐ Average Rating
B9: Category Performance Breakdown | M9: Customer Name | T9: 👥 Total Customers (Distinct Customer Name)
B10: Category | C10: Orders Count | D10: Total Revenue | E10: Total Profit | M10: City | T10: 🔄 Return Rate (%)
B11: Electronics | C11: =COUNTIF('Order Data'!F$2:F$1501, B11) -> 374 | D11: =SUMIF('Order Data'!F$2:F$1501, B11, 'Order Data'!M$2:M$1501) -> 16739190 | E11: =SUMIF('Order Data'!F$2:F$1501, B11, 'Order Data'!N$2:N$1501) -> 2951652.6 | M11: State | T11: 🚚 Delivery Success Rate
B12: Clothing & Fashion | C12: =COUNTIF('Order Data'!F$2:F$1501, B12) -> 376 | D12: =SUMIF('Order Data'!F$2:F$1501, B12, 'Order Data'!M$2:M$1501) -> 1282144.3 | E12: =SUMIF('Order Data'!F$2:F$1501, B12, 'Order Data'!N$2:N$1501) -> 220892.68 | M12: Category | T12: 💸 Average Order Value (AOV)
B13: Home & Kitchen | C13: =COUNTIF('Order Data'!F$2:F$1501, B13) -> 379 | D13: =SUMIF('Order Data'!F$2:F$1501, B13, 'Order Data'!M$2:M$1501) -> 1724233.3 | E13: =SUMIF('Order Data'!F$2:F$1501, B13, 'Order Data'!N$2:N$1501) -> 298014.25 | M13: Product
B14: Beauty & Grooming | C14: =COUNTIF('Order Data'!F$2:F$1501, B14) -> 371 | D14: =SUMIF('Order Data'!F$2:F$1501, B14, 'Order Data'!M$2:M$1501) -> 669482.85 | E14: =SUMIF('Order Data'!F$2:F$1501, B14, 'Order Data'!N$2:N$1501) -> 115659.3 | M14: Brand
B15: Total | C15: =SUM(C11:C14) -> 1500 | D15: =SUM(D11:D14) -> 20415050 | E15: =SUM(E11:E14) -> 3586218.8 | M15: Seller | T15: KPI | U15: Formula
M16: Quantity | T16: Total Orders | U16: COUNTA(Order ID)
M17: Unit Price | T17: Total Revenue | U17: SUM(Revenue)
M18: Discount | T18: Total Profit | U18: SUM(Profit)
D19: Product Analysis | F19: Payment Analysis | K19: Recommended Dashboard Layout | M19: Revenue | T19: Average Rating | U19: AVERAGE(Rating)
B20: 📦 Total Orders | M20: Profit | T20: Total Customers | U20: Remove Duplicates ya Pivot Table se Distinct Count
B21: 💰 Total Revenue | D21: Top 10 Products by Revenue | F21: Payment Mode Distribution | K21: Top Row (KPI Cards) | M21: Payment Mode | T21: Average Order Value | U21: Total Revenue / Total Orders
B22: 📈 Total Profit | D22: Top 10 Products by Profit | F22: UPI | M22: Delivery Status | T22: 📊 Top 10 Products by Revenue (Horizontal Bar)
B23: ⭐ Average Rating | D23: Category-wise Revenue | F23: Credit Card | K23: Total Orders | M23: Rating
B24: 👥 Total Customers (Distinct Customer Name) | D24: Category-wise Profit | F24: Debit Card | K24: Total Revenue | M24: Return Status
B25: 🔄 Return Rate (%) | D25: Brand-wise Sales | F25: Cash on Delivery | K25: Total Profit
B26: 🚚 Delivery Success Rate | D26: Brand-wise Profit | K26: Average Rating | T26: 🔹 Bottom Section
B27: 💸 Average Order Value (AOV) | F27: Pie Chart. | K27: Return Rate
K28: Average Order Value | T28: 🍩 Payment Mode Distribution (Donut Chart)
T29: 🍩 Delivery Status (Donut Chart)
D30: Customer Analysis | K30: Middle Row | T30: 🍩 Return Status (Donut Chart)
B31: Sales Analysis Charts | F31: Rating Analysis | T31: 📍 State-wise Revenue (Bar Chart)
D32: Top 10 Customers by Revenue | K32: Revenue Trend (Line Chart)
B33: Revenue by Month | D33: Top Customers by Orders | F33: Average Rating by Category | K33: Category-wise Revenue (Bar Chart)
B34: Profit by Month | D34: Average Rating by Customer (optional) | F34: Average Rating by Brand | K34: Brand-wise Revenue (Bar Chart)
B35: Orders by Month | F35: Rating Distribution (1–5) | T35: Slicers
B36: Revenue Trend Line | K36: Bottom Row
T37: Pivot Tables bana kar in par Slicers lagao:
D38: Location Analysis | K38: Revenue by State (Map/Bar)
F39: Discount Analysis | K39: Payment Mode (Donut Chart) | T39: Year
D40: Revenue by State | K40: Delivery Status (Donut Chart) | T40: Month
D41: Revenue by City | F41: Average Discount | K41: Return Status (Donut Chart) | T41: State
D42: Profit by State | F42: Discount vs Revenue | K42: Top 10 Products (Bar Chart) | T42: City
F43: Discount vs Profit | T43: Category
...

Sheet Revenue Analysis
A2: Row Labels | B2: Sum of Profit | C2: Sum of Revenue
A3: Feb | B3: 529692.77 | C3: 2977172.1
A4: Jan | B4: 525504.79 | C4: 2908282.4
A5: Mar | B5: 454232.11 | C5: 2549825.3
A6: Aug | B6: 255159.91 | C6: 1528879.4
A7: Nov | B7: 248307.71 | C7: 1462648
A8: Apr | B8: 260702.61 | C8: 1388847.4
A9: Dec | B9: 220765.1 | C9: 1369319.3
A10: Jun | B10: 228597.03 | C10: 1348702.9
A11: Sep | B11: 245911.29 | C11: 1307186.8
A12: Jul | B12: 215594.06 | C12: 1224880.3
A13: Oct | B13: 203420.53 | C13: 1222922.9
A14: May | B14: 198330.89 | C14: 1126383.4
A15: Grand Total | B15: 3586218.8 | C15: 20415050
A21: Row Labels | B21: Sum of Profit
A22: Jan | B22: 525504.79
A23: Feb | B23: 529692.77
A24: Mar | B24: 454232.11
A25: Apr | B25: 260702.61
A26: May | B26: 198330.89
A27: Jun | B27: 228597.03
A28: Jul | B28: 215594.06
A29: Aug | B29: 255159.91
A30: Sep | B30: 245911.29
A31: Oct | B31: 203420.53
A32: Nov | B32: 248307.71
A33: Dec | B33: 220765.1
A34: Grand Total | B34: 3586218.8

Sheet Order Analysis
A1: count order's | B1: Count of Order by mnoth
A2: Jan | B2: 197
A3: Feb | B3: 208
A4: Mar | B4: 190
A5: Apr | B5: 97
A6: May | B6: 92
A7: Jun | B7: 90
A8: Jul | B8: 108
A9: Aug | B9: 106
A10: Sep | B10: 106
A11: Oct | B11: 94
A12: Nov | B12: 105
A13: Dec | B13: 107
A14: Grand Total | B14: 1500
B23: Row Labels | C23: Sum of Revenue | D23: Count of Product
B24: Wireless Earbuds | C24: 3468185.2 | D24: 75
B25: Water Bottle | C25: 265097.95 | D25: 66
B26: Sunscreen | C26: 146897.65 | D26: 78
B27: Sports Shoes | C27: 144628.25 | D27: 49
B28: Socks Pack | C28: 237964 | D28: 69
B29: Smartwatch | C29: 2838978.7 | D29: 65
B30: Smartphone | C30: 2144681.8 | D30: 58
B31: Smart TV | C31: 2923156.6 | D31: 55
B32: Slim Fit Jeans | C32: 259345.75 | D32: 69
B33: Power Bank | C33: 2733564.9 | D33: 65
B34: Perfume | C34: 151620 | D34: 91
B35: Non-Stick Pan | C35: 294268.2 | D35: 62
... B47: Grand Total | C47: 20415050 | D47: 1500

Sheet Top_10 Revenue
A1: Row Labels | B1: Sum of Profit | C1: Sum of Revenue
A2: Wireless Earbuds | B2: 622732.38 | C2: 3468185.2
A3: Smart TV | B3: 544635.39 | C3: 2923156.6
A4: Smartwatch | B4: 487147.38 | C4: 2838978.7
A5: Power Bank | B5: 460228.22 | C5: 2733564.9
A6: Laptop | B6: 437719.66 | C6: 2630622.5
A7: Smartphone | B7: 399189.53 | C7: 2144681.8
A8: Air Fryer | B8: 53251.316 | C8: 305336.1
A9: Mixer Grinder | B9: 51694.889 | C9: 297233.75
A10: Non-Stick Pan | B10: 53722.295 | C10: 294268.2
A11: LED Bulb | B11: 50298.953 | C11: 288501.05
A12: Grand Total | B12: 3160620 | C12: 17924529
A21: Row Labels | B21: Sum of Revenue
A22: LED Bulb | B22: 288501.05
A23: Non-Stick Pan | B23: 294268.2
A24: Mixer Grinder | B24: 297233.75
A25: Air Fryer | B25: 305336.1
A26: Smartphone | B26: 2144681.8
A27: Laptop | B27: 2630622.5
A28: Power Bank | B28: 2733564.9
A29: Smartwatch | B29: 2838978.7
A30: Smart TV | B30: 2923156.6
A31: Wireless Earbuds | B31: 3468185.2
A32: Grand Total | B32: 17924529

Sheet Revenue Summary
A1: Row Labels | B1: Sum of Revenue
A2: Beauty & Grooming | B2: 669482.85
A3: Clothing & Fashion | B3: 1282144.3
A4: Electronics | B4: 16739190
A5: Home & Kitchen | B5: 1724233.3
A6: Grand Total | B6: 20415050
A19: Row Labels | B19: Sum of Revenue
A20: Asus | B20: 2630622.5
A21: Beardo | B21: 151620
A22: boAt | B22: 3468185.2
A23: Bombay Dyeing | B23: 273796.25
A24: Hawkins | B24: 294268.2
A25: Kent | B25: 305336.1
A26: L'Oreal | B26: 158199.25
A27: Levis | B27: 259345.75
A28: Mi | B28: 2733564.9
A29: Milton | B29: 265097.95
A30: Neutrogena | B30: 146897.65
A31: Nivea | B31: 115722.4
... A42: Grand Total | B42: 20415050

Sheet Average Summary
A1: customer name | B1: Average of Rating | C1: Sum of Revenue
A2: Yash Wardhan | B2: 4.0983607 | C2: 987490.6
A3: Sunil Gavaskar | B3: 3.96875 | C3: 1202643.2
A4: Sneha Reddy | B4: 3.71875 | C4: 913779.8
A5: Shilpa Shetty | B5: 3.9259259 | C5: 876876.9
A6: Sanjay Rao | B6: 3.9411765 | C6: 895619
A7: Rohan Das | B7: 4.0384615 | C7: 951539.8
A8: Pooja Nair | B8: 3.8461538 | C8: 880144.3
A9: Divya Dutta | B9: 4.0833333 | C9: 1264824.7
A10: Deepak Kumar | B10: 4.1129032 | C10: 1028778.8
A11: Aditi Rao | B11: 4.0149254 | C11: 1072427.3
A12: Grand Total | B12: 3.9761499 | C12: 10074124
A20: Row Labels | B20: Average of Rating
A21: Aditi Rao | B21: 4.0149254
A22: Arjun Choudhury | B22: 4.1272727
A23: Deepak Kumar | B23: 4.1129032
A24: Divya Dutta | B24: 4.0833333
A25: Jyoti Mishra | B25: 4.0961538
A26: Neha Gupta | B26: 4.0447761
A27: Rohan Das | B27: 4.0384615
A28: Vikram Singh | B28: 4.0142857
A29: Vivek Agnihotri | B29: 4.0545455
A30: Yash Wardhan | B30: 4.0983607
A31: Grand Total | B31: 4.0665557

Sheet KPI Summary
N2: Row Labels | O2: Count of Return Status
A3: Row Labels | B3: Count of Payment Mode | N3: No Return | O3: 1410
A4: Cash on Delivery (COD) | B4: 288 | N4: Not Applicable | O4: 55
A5: Credit Card | B5: 287 | N5: Returned | O5: 35
A6: Debit Card | B6: 299 | N6: Grand Total | O6: 1500
A7: Net Banking | B7: 307
A8: UPI | B8: 319
A9: Grand Total | B9: 1500
A17: Row Labels | B17: Count of Delivery Status
A18: Cancelled | B18: 55
A19: Delivered | B19: 1355
A20: Returned | B20: 35
A21: Shipped | B21: 55
A22: Grand Total | B22: 1500
N23: Row Labels | O23: Count of Seller
N24: IndiFlashMart | O24: 183
N25: OmniTechRetail | O25: 202
N26: RetailNet | O26: 384
N27: SaneRetails | O27: 177
N28: SuperComNet | O28: 188
N29: TrueComRetail | O29: 366
N30: Grand Total | O30: 1500
A40: Row Labels | B40: Sum of Revenue
A41: Gujarat | B41: 993050.4
A42: West Bengal | B42: 1079201.1
A43: Rajasthan | B43: 1215198.5
A44: Uttar Pradesh | B44: 1222993.1
A45: Tamil Nadu | B45: 1274288.5
A46: Punjab | B46: 1294748.4
A47: Telangana | B47: 1325238.9
A48: Karnataka | B48: 1422350.6
A49: Madhya Pradesh | B49: 1461531.5
A50: Bihar | B50: 1477911.6
A51: Kerala | B51: 1554327.6
A52: Assam | B52: 1581083.5
... A55: Grand Total | B55: 20415050
